<?xml version="1.0"?>
<robot name="my_robot">

  <link name="base_link">
    <visual>
      <geometry><box size="0.3 0.2 0.1"/></geometry>
      <material name="yellow"><color rgba="1 0.8 0 1"/></material>
    </visual>
    <collision>
      <geometry><box size="0.3 0.2 0.1"/></geometry>
    </collision>
    <inertial>
      <mass value="1.0"/>
      <inertia ixx="0.004167" ixy="0.0" ixz="0.0" iyy="0.008333" iyz="0.0" izz="0.010833"/>
    </inertial>
  </link>

  <link name="left_wheel">
    <visual>
      <geometry><cylinder radius="0.05" length="0.04"/></geometry>
      <material name="black"><color rgba="0 0 0 1"/></material>
    </visual>
    <collision>
      <geometry><cylinder radius="0.05" length="0.04"/></geometry>
    </collision>
    <inertial>
      <mass value="0.1"/>
      <inertia ixx="0.0000758" ixy="0.0" ixz="0.0" iyy="0.0000758" iyz="0.0" izz="0.000125"/>
    </inertial>
  </link>

  <link name="right_wheel">
    <visual>
      <geometry><cylinder radius="0.05" length="0.04"/></geometry>
      <material name="black"><color rgba="0 0 0 1"/></material>
    </visual>
    <collision>
      <geometry><cylinder radius="0.05" length="0.04"/></geometry>
    </collision>
    <inertial>
      <mass value="0.1"/>
      <inertia ixx="0.0000758" ixy="0.0" ixz="0.0" iyy="0.0000758" iyz="0.0" izz="0.000125"/>
    </inertial>
  </link>

  <link name="front_caster">
    <visual>
      <geometry><sphere radius="0.02"/></geometry>
      <material name="grey"><color rgba="0.5 0.5 0.5 1"/></material>
    </visual>
    <collision>
      <geometry><sphere radius="0.02"/></geometry>
    </collision>
    <inertial>
      <mass value="0.05"/>
      <inertia ixx="0.00001" ixy="0.0" ixz="0.0" iyy="0.00001" iyz="0.0" izz="0.00001"/>
    </inertial>
  </link>

  <link name="back_caster">
    <visual>
      <geometry><sphere radius="0.02"/></geometry>
      <material name="grey"><color rgba="0.5 0.5 0.5 1"/></material>
    </visual>
    <collision>
      <geometry><sphere radius="0.02"/></geometry>
    </collision>
    <inertial>
      <mass value="0.05"/>
      <inertia ixx="0.00001" ixy="0.0" ixz="0.0" iyy="0.00001" iyz="0.0" izz="0.00001"/>
    </inertial>
  </link>

  <link name="lidar_link">
    <visual>
      <geometry><cylinder radius="0.03" length="0.04"/></geometry>
      <material name="red"><color rgba="1 0 0 1"/></material>
    </visual>
    <collision>
      <geometry><cylinder radius="0.03" length="0.04"/></geometry>
    </collision>
    <inertial>
      <mass value="0.05"/>
      <inertia ixx="0.00001" ixy="0.0" ixz="0.0" iyy="0.00001" iyz="0.0" izz="0.00001"/>
    </inertial>
  </link>

  <link name="left_fork">
    <visual>
      <geometry><box size="0.35 0.04 0.02"/></geometry>
      <material name="dark_grey"><color rgba="0.2 0.2 0.2 1"/></material>
    </visual>
    <collision>
      <geometry><box size="0.35 0.04 0.02"/></geometry>
    </collision>
    <inertial>
      <mass value="0.05"/>
      <inertia ixx="0.00001" ixy="0.0" ixz="0.0" iyy="0.00001" iyz="0.0" izz="0.00001"/>
    </inertial>
  </link>

  <link name="right_fork">
    <visual>
      <geometry><box size="0.35 0.04 0.02"/></geometry>
      <material name="dark_grey"><color rgba="0.2 0.2 0.2 1"/></material>
    </visual>
    <collision>
      <geometry><box size="0.35 0.04 0.02"/></geometry>
    </collision>
    <inertial>
      <mass value="0.05"/>
      <inertia ixx="0.00001" ixy="0.0" ixz="0.0" iyy="0.00001" iyz="0.0" izz="0.00001"/>
    </inertial>
  </link>

  <link name="mast">
    <visual>
      <geometry><box size="0.05 0.18 0.35"/></geometry>
      <material name="dark_grey"><color rgba="0.2 0.2 0.2 1"/></material>
    </visual>
    <collision>
      <geometry><box size="0.05 0.18 0.35"/></geometry>
    </collision>
    <inertial>
      <mass value="0.1"/>
      <inertia ixx="0.0001" ixy="0.0" ixz="0.0" iyy="0.0001" iyz="0.0" izz="0.0001"/>
    </inertial>
  </link>

  <link name="camera_link">
    <visual>
      <geometry><box size="0.03 0.03 0.03"/></geometry>
      <material name="black"><color rgba="0 0 0 1"/></material>
    </visual>
    <collision>
      <geometry><box size="0.03 0.03 0.03"/></geometry>
    </collision>
    <inertial>
      <mass value="0.02"/>
      <inertia ixx="0.000005" ixy="0.0" ixz="0.0" iyy="0.000005" iyz="0.0" izz="0.000005"/>
    </inertial>
  </link>

  <joint name="left_wheel_joint" type="continuous">
    <parent link="base_link"/>
    <child link="left_wheel"/>
    <origin xyz="0.0 0.12 -0.025" rpy="-1.5708 0 0"/>
    <axis xyz="0 0 1"/>
  </joint>

  <joint name="right_wheel_joint" type="continuous">
    <parent link="base_link"/>
    <child link="right_wheel"/>
    <origin xyz="0.0 -0.12 -0.025" rpy="-1.5708 0 0"/>
    <axis xyz="0 0 1"/>
  </joint>

  <joint name="front_caster_joint" type="fixed">
    <parent link="base_link"/>
    <child link="front_caster"/>
    <origin xyz="0.12 0.0 -0.055" rpy="0 0 0"/>
  </joint>

  <joint name="back_caster_joint" type="fixed">
    <parent link="base_link"/>
    <child link="back_caster"/>
    <origin xyz="-0.12 0.0 -0.055" rpy="0 0 0"/>
  </joint>

  <joint name="lidar_joint" type="fixed">
    <parent link="base_link"/>
    <child link="lidar_link"/>
    <origin xyz="0.0 0.0 0.07" rpy="0 0 0"/>
  </joint>

  <joint name="left_fork_joint" type="fixed">
    <parent link="base_link"/>
    <child link="left_fork"/>
    <origin xyz="0.325 0.06 -0.06" rpy="0 0 0"/>
  </joint>

  <joint name="right_fork_joint" type="fixed">
    <parent link="base_link"/>
    <child link="right_fork"/>
    <origin xyz="0.325 -0.06 -0.06" rpy="0 0 0"/>
  </joint>

  <joint name="mast_joint" type="fixed">
    <parent link="base_link"/>
    <child link="mast"/>
    <origin xyz="0.16 0.0 0.225" rpy="0 0 0"/>
  </joint>

  <joint name="camera_joint" type="fixed">
    <parent link="base_link"/>
    <child link="camera_link"/>
    <origin xyz="0.19 0.0 0.4" rpy="0 0 0"/>
  </joint>

  <gazebo reference="base_link"><material>Gazebo/Yellow</material></gazebo>
  <gazebo reference="left_wheel"><material>Gazebo/Black</material></gazebo>
  <gazebo reference="right_wheel"><material>Gazebo/Black</material></gazebo>
  <gazebo reference="left_fork"><material>Gazebo/Grey</material></gazebo>
  <gazebo reference="right_fork"><material>Gazebo/Grey</material></gazebo>
  <gazebo reference="mast"><material>Gazebo/Grey</material></gazebo>
  <gazebo reference="camera_link"><material>Gazebo/Black</material></gazebo>
  <gazebo reference="front_caster">
    <material>Gazebo/Grey</material>
    <mu1>0.0</mu1>
    <mu2>0.0</mu2>
  </gazebo>
  <gazebo reference="back_caster">
    <material>Gazebo/Grey</material>
    <mu1>0.0</mu1>
    <mu2>0.0</mu2>
  </gazebo>
  <gazebo reference="lidar_link">
    <material>Gazebo/Red</material>
    <sensor type="ray" name="lidar_sensor">
      <pose>0 0 0 0 0 0</pose>
      <visualize>true</visualize>
      <update_rate>10</update_rate>
      <ray>
        <scan>
          <horizontal>
            <samples>360</samples>
            <resolution>1</resolution>
            <min_angle>-3.14159</min_angle>
            <max_angle>3.14159</max_angle>
          </horizontal>
        </scan>
        <range>
          <min>0.12</min>
          <max>10.0</max>
          <resolution>0.015</resolution>
        </range>
      </ray>
      <plugin name="lidar_plugin" filename="libgazebo_ros_ray_sensor.so">
        <ros>
          <remapping>~/out:=scan</remapping>
        </ros>
        <output_type>sensor_msgs/LaserScan</output_type>
        <frame_name>lidar_link</frame_name>
      </plugin>
    </sensor>
  </gazebo>

  <gazebo reference="camera_link">
    <sensor type="camera" name="camera">
      <pose>0 0 0 0 0 0</pose>
      <visualize>true</visualize>
      <update_rate>30</update_rate>
      <camera>
        <horizontal_fov>1.396</horizontal_fov>
        <image>
          <width>640</width>
          <height>480</height>
          <format>R8G8B8</format>
        </image>
        <clip>
          <near>0.05</near>
          <far>15</far>
        </clip>
      </camera>
      <plugin name="camera_controller" filename="libgazebo_ros_camera.so">
        <camera_name>forklift_camera</camera_name>
        <frame_name>camera_link</frame_name>
      </plugin>
    </sensor>
  </gazebo>

  <gazebo>
    <plugin name="diff_drive" filename="libgazebo_ros_diff_drive.so">
      <left_joint>left_wheel_joint</left_joint>
      <right_joint>right_wheel_joint</right_joint>
      <wheel_separation>0.24</wheel_separation>
      <wheel_diameter>0.1</wheel_diameter>
      <max_wheel_torque>20</max_wheel_torque>
      <max_wheel_acceleration>1.0</max_wheel_acceleration>
      <publish_odom>true</publish_odom>
      <publish_odom_tf>true</publish_odom_tf>
      <publish_wheel_tf>true</publish_wheel_tf>
      <odometry_frame>odom</odometry_frame>
      <robot_base_frame>base_link</robot_base_frame>
    </plugin>
  </gazebo>

</robot>
